{
  "xsize": 16,
  "zsize": 16,
  "slices": [
    [
      "################",
      "################",
      "################",
      "################",
      "################",
      "################",
      "################",
      "################",
      "################",
      "#######l########",
      "####1###########",
      "################",
      "################",
      "################",
      "################",
      "################"
    ],
    [
      "#aa@  aa aa @aa#",
      "a  F      QQQ  a",
      "a              a",
      "@              @",
      "                ",
      "              Fa",
      "               a",
      "               a",
      "a               ",
      "a      l        ",
      "a###########  #a",
      "a              a",
      "@              @",
      "a              a",
      "a              a",
      "#aa@   aaaaa@  #"
    ],
    [
      "#aa@  aa   a@a #",
      "a         **   a",
      "a              a",
      "@              @",
      "                ",
      "                ",
      "               a",
      "               a",
      "a              a",
      "a    T l       a",
      "a#::########  #a",
      "a    T         a",
      "@              @",
      "a              a",
      "a              a",
      "#aa@    aaaa@  #"
    ],
    [
      "#  @aaaaaaaa@aa#",
      "a              a",
      "a              a",
      "@              @",
      "               a",
      "               a",
      "               a",
      "a               ",
      "a               ",
      "a      l        ",
      "a##############a",
      "a              a",
      "@              @",
      "a              a",
      "a              a",
      "# a@    aaaa@aa#"
    ],
    [
      "################",
      "################",
      "################",
      "################",
      "################",
      "################",
      "################",
      "################",
      "################",
      "#######l########",
      "################",
      "################",
      "################",
      "################",
      "################",
      "################"
    ],
    [
      "################",
      "################",
      "################",
      "################",
      "################",
      "################",
      "################",
      "################",
      "################",
      "#######l########",
      "################",
      "################",
      "################",
      "################",
      "################",
      "################"
    ]
  ]
}