{
  "xsize": 16,
  "zsize": 16,
  "slices": [
    [
      "################",
      "################",
      "################",
      "################",
      "################",
      "################",
      "################",
      "################",
      "################",
      "####X1XlX1X#####",
      "################",
      "################",
      "################",
      "################",
      "################",
      "################"
    ],
    [
      "# a@aaaaaaaa@  #",
      "a   LL         a",
      "a              a",
      "@              @",
      "               a",
      "               a",
      "     ## ##     a",
      "     #   #      ",
      "a    #   #      ",
      "a    X l X      ",
      "a  QQ#####QQ   a",
      "a      CF      a",
      "@              @",
      "               a",
      "a              a",
      "#aa@  aaaaaa@aa#"
    ],
    [
      "#  @ aa a  a@  #",
      "a   LL          ",
      "               a",
      "@              @",
      "                ",
      "               a",
      "     ## ##     a",
      "a    #  T#     a",
      "a    #   #     a",
      "a    # l #      ",
      "a  QQ#####QQ    ",
      "a              a",
      "@              @",
      "               a",
      "               a",
      "#aa@  aaaaaa@aa#"
    ],
    [
      "#aa@aaaaaaaa@aa#",
      "a              a",
      "a              a",
      "@              @",
      "a              a",
      "a              a",
      "a    #####     a",
      "a    #   #     a",
      "a    #   #     a",
      "a    # l #     a",
      "a  QQ#####QQ   a",
      "a              a",
      "@              @",
      "a              a",
      "a              a",
      "#aa@aaaaaaaa@aa#"
    ],
    [
      "################",
      "################",
      "################",
      "################",
      "################",
      "################",
      "################",
      "################",
      "################",
      "#######l########",
      "################",
      "################",
      "################",
      "################",
      "################",
      "################"
    ],
    [
      "################",
      "################",
      "################",
      "################",
      "################",
      "################",
      "################",
      "################",
      "################",
      "#######l########",
      "################",
      "################",
      "################",
      "################",
      "################",
      "################"
    ]
  ]
}