{
  "xsize": 16,
  "zsize": 16,
  "slices": [
    [
      "################",
      "################",
      "################",
      "################",
      "################",
      "################",
      "################",
      "################",
      "################",
      "#######l########",
      "################",
      "################",
      "################",
      "################",
      "################",
      "################"
    ],
    [
      "#aa@aaa   aa@aa#",
      "a              a",
      "a               ",
      "@              @",
      "               a",
      "               a",
      "     ## ##     a",
      "     #   ######a",
      "a              a",
      "a    # l #     a",
      "a    #####      ",
      "a      F#       ",
      "@       #      @",
      "               a",
      "a       #      a",
      "#  @aaaaaaaa@aa#"
    ],
    [
      "#aa@aa    aa@aa#",
      "a              a",
      "a               ",
      "@              @",
      "a              a",
      "               a",
      "     ## ##     a",
      "     #   ###:##a",
      "a          T T a",
      "a    # l #     a",
      "a    #####      ",
      "a       #       ",
      "@       #      @",
      "a              a",
      "a       #      a",
      "#  @aaa   aa@aa#"
    ],
    [
      "#aa@aaaaaaaa@aa#",
      "a              a",
      "a              a",
      "@              @",
      "a              a",
      "a              a",
      "a    #####     a",
      "a    #   ######a",
      "a    #   #     a",
      "a    # l #     a",
      "a    #####     a",
      "a       #      a",
      "@       #      @",
      "a       #      a",
      "a       #      a",
      "#aa@aaaaaaaa@aa#"
    ],
    [
      "################",
      "################",
      "################",
      "################",
      "################",
      "################",
      "################",
      "################",
      "################",
      "#######l########",
      "################",
      "################",
      "################",
      "################",
      "################",
      "################"
    ],
    [
      "################",
      "################",
      "################",
      "################",
      "################",
      "################",
      "################",
      "################",
      "################",
      "#######l########",
      "################",
      "################",
      "################",
      "################",
      "################",
      "################"
    ]
  ]
}