{
  "xsize": 16,
  "zsize": 16,
  "slices": [
    [
      "################",
      "################",
      "################",
      "################",
      "################",
      "################",
      "################",
      "################",
      "################",
      "#######l########",
      "##########1#####",
      "################",
      "################",
      "################",
      "################",
      "################"
    ],
    [
      "#aa@a aa  aa@aa#",
      "a  #        #  a",
      "a  #F       #  a",
      "@  #F      L#  @",
      "a  #D      L#  a",
      "a  #        #  a",
      "               a",
      "a  #        #  a",
      "a  #        #  a",
      "a  #   l    #  a",
      "a  ##########  a",
      "a               ",
      "@              @",
      "a              a",
      "a     F        a",
      "#aa@aaaaaaaa@aa#"
    ],
    [
      "#aa@a aaa aa@aa#",
      "a  #        #  a",
      "a  #        #  a",
      "@  #       L#  @",
      "   #*      L#  a",
      "a  #        #  a",
      "a              a",
      "   #        #   ",
      "a  #        #  a",
      "a  #   l    #  a",
      "a  ##########  a",
      "a       T       ",
      "@              @",
      "a              a",
      "a              a",
      "#aa@aaa aaa @aa#"
    ],
    [
      "#aa@aaa aaaa@aa#",
      "a  #        #  a",
      "a  #        #  a",
      "@  #        #  @",
      "a  #        #  a",
      "a  #        #   ",
      "a  #        #  a",
      "a  #        #  a",
      "a  #        #  a",
      "a  #   l    #  a",
      "   ##########  a",
      "a              a",
      "@              @",
      "a              a",
      "a              a",
      "#aa@aaa aaa @aa#"
    ],
    [
      "################",
      "################",
      "################",
      "################",
      "################",
      "################",
      "################",
      "################",
      "################",
      "#######l########",
      "################",
      "################",
      "################",
      "################",
      "################",
      "################"
    ],
    [
      "################",
      "################",
      "################",
      "################",
      "################",
      "################",
      "################",
      "################",
      "################",
      "#######l########",
      "################",
      "################",
      "################",
      "################",
      "################",
      "################"
    ]
  ]
}