{
  "xsize": 16,
  "zsize": 16,
  "slices": [
    [
      "##   #aaaa#   ##",
      "######QSQS######",
      " #SQSQSQSQSQSQSQ",
      " #QSQSQSQSQSQSQS",
      " #SQSQSQSQSQSQSQ",
      "##QSQSQSQSQSQSQS",
      "aQSQSQSQSQSQSQSQ",
      "aSQSQSQSQSQSQSQS",
      "aQSQSQSQSQSQSQSQ",
      "aSQSQSQSQSQSQSQS",
      "##SQSQSQSQSQS  Q",
      " #QSQSQSQSQSQ  S",
      " #SQSQSQSQSQS  Q",
      " #QSQSQSQSQSQ  S",
      "##SQSQSQSQSQS))Q",
      "##QSQSQSQSQSQSQS"
    ],
    [
      "##   #aaaa#   ##",
      "##aa #    #   ##",
      " a              ",
      "                ",
      "                ",
      "##              ",
      "a               ",
      "a               ",
      "                ",
      "a            )) ",
      "#########   Q  Q",
      " a FF ###   Q  Q",
      " a    ###   Q  Q",
      " a    ###   Q  Q",
      "### #####   Q  Q",
      "##              "
    ],
    [
      "##   #aaaa#   ##",
      "##  a#    #    ##",
      "                ",
      "                ",
      " a              ",
      "##              ",
      "a               ",
      "a               ",
      "                ",
      "a    T          ",
      "#########   a))a",
      " a    ###   a  a",
      " a    ###   a  a",
      " a    ###   a  a",
      "### #####   a  a",
      "##              "
    ],
    [
      "##   #    #   ##",
      "##aaa#    #aaa##",
      "                ",
      "                ",
      "                ",
      "##              ",
      "a               ",
      "a               ",
      "a               ",
      "a               ",
      "#########   a  a",
      " a    ###   a))a",
      " a    ###   a  a",
      " a    ###   a  a",
      "### #####   a  a",
      "##              "
    ],
    [
      "##   #aaaa#   ##",
      "##aaa#    #aaa##",
      " a              ",
      "                ",
      " a              ",
      "##              ",
      "a               ",
      "a               ",
      "                ",
      "                ",
      "#########   a  a",
      " a    ###   a  a",
      " a    ###   a))a",
      " a    ###   a  a",
      "### #####   a  a",
      "##              "
    ],
    [
      "##   #aaaa#   ##",
      "################",
      " ###############",
      " ###############",
      " ###############",
      "################",
      "a###############",
      "a###############",
      "a###############",
      "a###############",
      "#############  #",
      " ############  #",
      " ############  #",
      " ############))#",
      "#############  #",
      "################"
    ]
  ]
}