{
  "xsize": 16,
  "zsize": 16,
  "slices": [
    [
      "#SS#QQQQQQQQQQQQ",
      "#SS#QQQQQQQQQQQQ",
      "#SS#QQQQQQQQQQQQ",
      "#SS#QQQQQQQQQQQQ",
      "#SS#QQQQQQQQQQQQ",
      "#SS#QQQQQQQQQQQQ",
      "#SS#QQQQQQQQQQQQ",
      "#SS#QQQQQQQQQQQQ",
      "#SS#QQQQQQQQQQQQ",
      "#SS#QQQQQQQQQQQQ",
      "#SS#QQQQQQQQQQQQ",
      "#SS#QQQQQQQQQQQQ",
      "#SS#############",
      "#SSSSSSSSSSSSSSS",
      "#SSSSSSSSSSSSSSS",
      "################"
    ],
    [
      "a               ",
      "                ",
      "a               ",
      "#               ",
      "a               ",
      "                ",
      "                ",
      "a               ",
      "###:::::::###   ",
      "a               ",
      "a   LLL     #   ",
      "a           :   ",
      "a   LLL     :   ",
      "#           #   ",
      "a F         #   ",
      "aa#aaaa#aaaa#a a"
    ],
    [
      "a               ",
      "a               ",
      "a               ",
      "#               ",
      "a               ",
      "                ",
      "                ",
      "a               ",
      "###:::::::###   ",
      "a               ",
      "a   LLL     #   ",
      "a           :   ",
      "a   LLLT    :   ",
      "#           #   ",
      "a           #   ",
      "aa#aaaa#aaaa#a a"
    ],
    [
      "a               ",
      "a               ",
      "a               ",
      "#               ",
      "a               ",
      "                ",
      "                ",
      "a               ",
      "###:::::::###   ",
      "a           #   ",
      "a   LLL     #   ",
      "            :   ",
      "a   LLL     :   ",
      "#           #   ",
      "a           #   ",
      "aa#aaaa#aaaa#   "
    ],
    [
      "#               ",
      "#               ",
      "#               ",
      "#               ",
      "#               ",
      "#               ",
      "#               ",
      "#               ",
      "###:::::::###   ",
      "#           #   ",
      "#           #   ",
      "#           :   ",
      "#           :   ",
      "#           #   ",
      "#           #   ",
      "################"
    ],
    [
      "################",
      "################",
      "################",
      "################",
      "################",
      "################",
      "################",
      "################",
      "################",
      "################",
      "################",
      "################",
      "################",
      "################",
      "################",
      "################"
    ]
  ]
}