{
  "xsize": 16,
  "zsize": 16,
  "slices": [
    [
      "#SS#QQQQQQQQQQQQ",
      "#SS#QQQQQQQQQQQQ",
      "#SS#QQQQQQQQQQQQ",
      "#SS#QQQQQQQQQQQQ",
      "#SS#QQQQQQQQQQQQ",
      "#SS#QQQQQQQQQQQQ",
      "#SS#QQQQQQQQQQQQ",
      "#SS#QQQQQQQQQQQQ",
      "#SS#QQQQQQQQQQQQ",
      "#SS#QQQQQQQQQQQQ",
      "#SS#QQQQQQQQQQQQ",
      "#SS#QQQQQQQQQQQQ",
      "#SS#############",
      "#SSSSSSSSSSSSSSS",
      "#SSSSSSSSSSSSSSS",
      "################"
    ],
    [
      "                ",
      "                ",
      "                ",
      "#               ",
      "a      LLLL     ",
      "a     QQQQQQ    ",
      "a     QLLLLQ    ",
      "a     Q    Q    ",
      "#               ",
      "a     Q    Q    ",
      "a     QLLLLQ    ",
      "a     QQQQQQ    ",
      "a      LLLL     ",
      "#               ",
      "a               ",
      "aa#aa  #  aa#aaa"
    ],
    [
      "a               ",
      "                ",
      "a               ",
      "#               ",
      "a               ",
      "       **       ",
      "                ",
      "a               ",
      "#               ",
      "a               ",
      "a               ",
      "a        * *    ",
      "                ",
      "#               ",
      "a               ",
      "aa#a   # aaa#aaa"
    ],
    [
      "a               ",
      "a               ",
      "a               ",
      "#               ",
      "a               ",
      "a               ",
      "a               ",
      "a               ",
      "#               ",
      "a               ",
      "a               ",
      "a               ",
      "a               ",
      "#               ",
      "a               ",
      "  #aaaa#aaaa#aaa"
    ],
    [
      "#               ",
      "#               ",
      "#               ",
      "#               ",
      "#               ",
      "#               ",
      "#               ",
      "#               ",
      "#               ",
      "#               ",
      "#               ",
      "#               ",
      "#               ",
      "#               ",
      "#               ",
      "################"
    ],
    [
      "################",
      "################",
      "################",
      "################",
      "################",
      "################",
      "################",
      "################",
      "################",
      "################",
      "################",
      "################",
      "################",
      "################",
      "################",
      "################"
    ]
  ]
}