{
  "xsize": 16,
  "zsize": 16,
  "slices": [
    [
      "#SSSSSSSSSSSSSS#",
      "S##############S",
      "S##############S",
      "S##############S",
      "S##############S",
      "S##############S",
      "S#####1########S",
      "S##############S",
      "S##############S",
      "S##############S",
      "S#########  ###S",
      "S#########  ###S",
      "S#########  ###S",
      "S#########cc###S",
      "S##############S",
      "#SSSSSSSSSSSSSS#"
    ],
    [
      "#a #aa#aa#aa#  #",
      "a     #        a",
      "a     #        a",
      "#C             #",
      "a     #        a",
      "      #        a",
      "#######        #",
      "a    S#        a",
      "a    S#   cc   a",
      "#    S#  :dd:  #",
      "a     #  :  :  a",
      "a        :  :  a",
      "#    F#  :  :  #",
      "a    F#         ",
      "a     #        a",
      "#aa#aa#aa#  #aa#"
    ],
    [
      "#  #aa#aa#aa#  #",
      "a     #        a",
      "a     #        a",
      "#              #",
      "a     #         ",
      "      #         ",
      "##:::##T       #",
      "a     #        a",
      "a    *#        a",
      "#    *#   cc   #",
      "a     #   dd   a",
      "a               ",
      "#     #        #",
      "a     #         ",
      "a     #         ",
      "#aa#aa#aa#  #aa#"
    ],
    [
      "#aa# a#aa#a #aa#",
      "a     #        a",
      "a     #        a",
      "#     #        #",
      "      #        a",
      "a     #        a",
      "#######        #",
      "a     #         ",
      "a     #        a",
      "#     #        #",
      "a     #   cc   a",
      "a     #   dd   a",
      "#     #        #",
      "a     #        a",
      "a     #        a",
      "#aa#aa#aa# a#aa#"
    ],
    [
      "#SSSSSSSSSSSSSS#",
      "S##############S",
      "S##############S",
      "S##############S",
      "S##############S",
      "S##############S",
      "S##############S",
      "S##############S",
      "S#########  ###S",
      "S#########  ###S",
      "S#########  ###S",
      "S#########cc###S",
      "S##############S",
      "S##############S",
      "S##############S",
      "#SSSSSSSSSSSSSS#"
    ],
    [
      "################",
      "################",
      "################",
      "################",
      "################",
      "################",
      "################",
      "################",
      "################",
      "##########  ####",
      "##########  ####",
      "##########  ####",
      "##########cc####",
      "################",
      "################",
      "################"
    ]
  ]
}