{
  "xsize": 16,
  "zsize": 16,
  "slices": [
    [
      "#$$#$$#$$#$$#$$#",
      "$##############$",
      "$###1##########$",
      "################",
      "$#####1########$",
      "$##############$",
      "################",
      "$##############$",
      "$##############$",
      "#######l########",
      "$##############$",
      "$##############$",
      "################",
      "$##############$",
      "$##############$",
      "#$$#$$#$$#$$#$$#"
    ],
    [
      "################",
      "#              #",
      "#   ###        #",
      "#   ###        #",
      "#   ###        #",
      "#              #",
      "##########     #",
      "#        #     #",
      "#        #     #",
      "#      l #     #",
      "#  #######    F#",
      "#             F#",
      "#             L#",
      "#              #",
      "#              #",
      "################"
    ],
    [
      "#aa#aa#  #aa#a #",
      "a              a",
      "a              a",
      "#    C         #",
      "               a",
      "a       T      a",
      "####aaa###     #",
      "a       T#     a",
      "a        #     a",
      "#      l #     #",
      "a  #######     a",
      "a              a",
      "#             L#",
      "a              a",
      "a               ",
      "#aa#  #a #aa# a#"
    ],
    [
      "#aa#aa#  #aa# a#",
      "a              a",
      "a              a",
      "#              #",
      "               a",
      "               a",
      "##########     #",
      "a        #     a",
      "a        #     a",
      "#      l #     #",
      "a  #######     a",
      "a              a",
      "#             L#",
      "a               ",
      "a               ",
      "#aa#  #aa#aa#aa#"
    ],
    [
      "################",
      "################",
      "################",
      "################",
      "################",
      "################",
      "################",
      "################",
      "################",
      "#######l########",
      "################",
      "################",
      "################",
      "################",
      "################",
      "################"
    ],
    [
      "################",
      "################",
      "################",
      "################",
      "################",
      "################",
      "################",
      "################",
      "################",
      "#######l########",
      "################",
      "################",
      "################",
      "################",
      "################",
      "################"
    ]
  ]
}