{
  "xsize": 16,
  "zsize": 16,
  "slices": [
    [
      "##   ######   ##",
      "################",
      " ############## ",
      " ############## ",
      " ############## ",
      "############1###",
      "################",
      "################",
      "################",
      "#######l########",
      "####1###########",
      " ############## ",
      " ############## ",
      " ############## ",
      "################",
      "##   ######   ##"
    ],
    [
      "##   ######   ##",
      "##   #    #aaa##",
      " a              ",
      " a              ",
      " a              ",
      "#### ###########",
      "#       FF     #",
      "#              #",
      "#              #",
      "#      l      C#",
      "########### ####",
      " a              ",
      "              a ",
      "              a ",
      "##aaa#    #  a##",
      "##   ######   ##"
    ],
    [
      "##   ######   ##",
      "##a a#    #   ##",
      " a              ",
      " a              ",
      " a     T      a ",
      "#### ###########",
      "#      T       #",
      "#              #",
      "#              #",
      "#      l       #",
      "########### ####",
      " a              ",
      " a              ",
      "              a ",
      "##aaa#    #   ##",
      "##   ######   ##"
    ],
    [
      "##   ######   ##",
      "##aaa#    #   ##",
      "              a ",
      "              a ",
      " a              ",
      "################",
      "#            %%#",
      "#              #",
      "#              #",
      "#%     l      %#",
      "################",
      " a              ",
      " a              ",
      " a              ",
      "##aaa#    #   ##",
      "##   ######   ##"
    ],
    [
      "##   ######   ##",
      "################",
      " ############## ",
      " ############## ",
      " ############## ",
      "################",
      "################",
      "################",
      "################",
      "#######l########",
      "################",
      " ############## ",
      " ############## ",
      " ############## ",
      "################",
      "##   ######   ##"
    ],
    [
      "##   ######   ##",
      "################",
      " ############## ",
      " ############## ",
      " ############## ",
      "################",
      "################",
      "################",
      "################",
      "#######l########",
      "################",
      " ############## ",
      " ############## ",
      " ############## ",
      "################",
      "##   ######   ##"
    ]
  ]
}