{
  "xsize": 16,
  "zsize": 16,
  "slices": [
    [
      "################",
      "################",
      "################",
      "################",
      "################",
      "################",
      "################",
      "################",
      "################",
      "#######l########",
      "################",
      "################",
      "################",
      "################",
      "################",
      "################"
    ],
    [
      "#aa@aa   aaa@  #",
      "a              a",
      "a              a",
      "@              @",
      "a              a",
      "a              a",
      "a    QQQQQ:::::a",
      "a    Q   Q      ",
      "a    Q   Q     a",
      "       l        ",
      "     QQQQQ      ",
      "a              a",
      "@              @",
      "a              a",
      "a              a",
      "#aa@   aaaa @aa#"
    ],
    [
      "#aa@    aaaa@  #",
      "a              a",
      "a              a",
      "@              @",
      "a              a",
      "a              a",
      "a    QQQQQ:::::a",
      "a    Q   Q      ",
      "a    Q   Q      ",
      "       l        ",
      "     QQQQQ      ",
      "               a",
      "@              @",
      "a              a",
      "a              a",
      "#aa@   aaaaa@aa#"
    ],
    [
      "#aa@aaaaaaaa@aa#",
      "a              a",
      "a              a",
      "@              @",
      "a              a",
      "a              a",
      "a    QQQQQ:::::a",
      "a    Q   Q     a",
      "a    Q   Q     a",
      "a    Q l Q     a",
      "a    QQQQQ     a",
      "a              a",
      "@              @",
      "a              a",
      "a              a",
      "#aa@aaaaaaaa@aa#"
    ],
    [
      "################",
      "################",
      "################",
      "################",
      "################",
      "################",
      "################",
      "################",
      "################",
      "#######l########",
      "################",
      "################",
      "################",
      "################",
      "################",
      "################"
    ],
    [
      "################",
      "################",
      "################",
      "################",
      "################",
      "################",
      "################",
      "################",
      "################",
      "#######l########",
      "################",
      "################",
      "################",
      "################",
      "################",
      "################"
    ]
  ]
}