{
  "xsize": 16,
  "zsize": 16,
  "slices": [
    [
      "##   #aaaa#   ##",
      "######QSQS######",
      " #SQSQSQSQSQSQSQ",
      " #QSQSQSQSQSQSQS",
      " #SQSQSQSQSQSQSQ",
      "##QSQSQSQSQSQSQS",
      "aQSQSQSQSQSQSQSQ",
      "aSQSQSQSQSQSQSQS",
      "aQSQSQSQSQSQSQSQ",
      "aSQSQSQSQSQSQSQS",
      "##SQSQSQSQSQS  Q",
      " #QSQSQSQSQSQ  S",
      " #SQSQSQSQSQS  Q",
      " #QSQSQSQSQSQ  S",
      "##SQSQSQSQSQS))Q",
      "##QSQSQSQSQSQSQS"
    ],
    [
      "##   #a aa#   ##",
      "##   #    #aaa##",
      " a              ",
      " a              ",
      " a              ",
      "##              ",
      "a               ",
      "                ",
      "                ",
      "a            )) ",
      "#########   Q  Q",
      " a CC #1#   Q  Q",
      " a    #1#   Q  Q",
      " a    #1#   Q  Q",
      "### #####   Q  Q",
      "##              "
    ],
    [
      "##   #a  a#   ##",
      "##a  #    #aaa##",
      " a              ",
      " a              ",
      " a              ",
      "##              ",
      "a               ",
      "                ",
      "a               ",
      "a    T          ",
      "#########   a))a",
      " a    ###   a  a",
      " a    ###   a  a",
      " a    ###   a  a",
      "### #####   a  a",
      "##              "
    ],
    [
      "##   #    #   ##",
      "##aa #    #aaa##",
      " a              ",
      " a              ",
      " a              ",
      "##              ",
      "                ",
      "                ",
      "                ",
      "                ",
      "#########   a  a",
      " a    #4#   a))a",
      " a    #1#   a  a",
      " a    #1#   a  a",
      "### #####   a  a",
      "##              "
    ],
    [
      "##   #aaaa#   ##",
      "##aaa#    #aaa##",
      " a              ",
      " a              ",
      " a              ",
      "##              ",
      "a               ",
      "a               ",
      "a               ",
      "a               ",
      "#########   a  a",
      " a    ###   a  a",
      " a    ###   a))a",
      " a    ###   a  a",
      "### #####   a  a",
      "##              "
    ],
    [
      "##   #aaaa#   ##",
      "################",
      " ###############",
      " ###############",
      " ###############",
      "################",
      "a###############",
      "a###############",
      "a###############",
      "a###############",
      "#############  #",
      " ############  #",
      " ############  #",
      " ############))#",
      "#############  #",
      "################"
    ]
  ]
}