{
  "xsize": 16,
  "zsize": 16,
  "slices": [
    [
      "################",
      "#SSSSSSSSSSSSSSS",
      "#SSSSSSSSSSSSSSS",
      "#SS#############",
      "#SS#QQQQQQQQQQQQ",
      "#SS#QQQQQQQQQQQQ",
      "#SS#QQQQQQQQQQQQ",
      "#SS#QQQQQQQQQQQQ",
      "#SS#QQQQQQQQQQQQ",
      "#SS#QQQQQQQQQQQQ",
      "#SS#QQQQQQQQQ  Q",
      "#SS#QQQQQQQQQ  Q",
      "#SS#QQQQQQQQQ  Q",
      "#SS#QQQQQQQQQ  Q",
      "#SS#QQQQQQQQQ))Q",
      "#SS#QQQQQQQQQQQQ"
    ],
    [
      "aa#    #aaaa#aaa",
      "a               ",
      "#               ",
      "a               ",
      "a      LLLL     ",
      "a               ",
      "a      LLLL     ",
      "#               ",
      "a               ",
      "a            )) ",
      "a           w  w",
      "a           w  w",
      "#           w  w",
      "            w  w",
      "            w  w",
      "a               "
    ],
    [
      "aa#  aa#aaaa# aa",
      "a               ",
      "#               ",
      "a               ",
      "       LLLLT    ",
      "                ",
      "a      LLLLT    ",
      "#               ",
      "                ",
      "a               ",
      "a           :)):",
      "a           :  :",
      "#           :  :",
      "            :  :",
      "            :  :",
      "a               "
    ],
    [
      "aa#  aa#aaaa#   ",
      "a               ",
      "#               ",
      "a               ",
      "a      LLLL     ",
      "                ",
      "a      LLLL     ",
      "#               ",
      "                ",
      "                ",
      "            :  :",
      "            :)):",
      "#           :  :",
      "a           :  :",
      "a           :  :",
      "a               "
    ],
    [
      "################",
      "#        %      ",
      "#               ",
      "#               ",
      "#               ",
      "#               ",
      "#               ",
      "#               ",
      "#               ",
      "#               ",
      "#          %:  :",
      "#           :  :",
      "#           :)):",
      "#          %:  :",
      "#           :  :",
      "#               "
    ],
    [
      "################",
      "################",
      "################",
      "################",
      "################",
      "################",
      "################",
      "################",
      "################",
      "################",
      "#############  #",
      "#############  #",
      "#############  #",
      "#############))#",
      "#############  #",
      "################"
    ]
  ]
}