{
  "xsize": 16,
  "zsize": 16,
  "slices": [
    [
      "#SS#QQQQQQQQQQQQ",
      "#SS#QQQQQQQQQQQQ",
      "#SS#QQQQQQQQQQQQ",
      "#SS#QQQQQQQQQQQQ",
      "#SS#QQQQQQQQQQQQ",
      "#SS#QQQQQQQQQQQQ",
      "#SS#QQQQQQQQQQQQ",
      "#SS#QQQQQQQQQQQQ",
      "#SS#QQQQQQQQQQQQ",
      "#SS#QQQQQQQQQQQQ",
      "#SS#QQQQQQQQQQQQ",
      "#SS#QQQQQQQQQQQQ",
      "#SS#############",
      "#SSSSSSSSSSSSSSS",
      "#SSSSSSSSSSSSSSS",
      "################"
    ],
    [
      "a               ",
      "a               ",
      "a               ",
      "#       %       ",
      "       LLLL     ",
      "                ",
      "a      LLLL     ",
      "a        %%     ",
      "#      LLLL     ",
      "a               ",
      "       LLLL     ",
      "a      %%       ",
      "a               ",
      "#               ",
      "a               ",
      "aa#aaaa#aaaa#   "
    ],
    [
      "a               ",
      "a               ",
      "a               ",
      "#               ",
      "       LLLLT    ",
      "                ",
      "a      LLLL     ",
      "a               ",
      "#      LLLL     ",
      "                ",
      "a      LLLLT    ",
      "a               ",
      "a               ",
      "#               ",
      "a               ",
      "aa#aaaa#aaaa#   "
    ],
    [
      "a               ",
      "a               ",
      "a               ",
      "#               ",
      "a      LLLL     ",
      "a               ",
      "a      LLLL     ",
      "a               ",
      "#      LLLL     ",
      "a               ",
      "a      LLLL     ",
      "a               ",
      "a               ",
      "#               ",
      "a               ",
      "aa#    #aaaa#aaa"
    ],
    [
      "#               ",
      "#               ",
      "#               ",
      "#               ",
      "#               ",
      "#               ",
      "#               ",
      "#               ",
      "#               ",
      "#               ",
      "#               ",
      "#               ",
      "#               ",
      "#               ",
      "#               ",
      "################"
    ],
    [
      "################",
      "################",
      "################",
      "################",
      "################",
      "################",
      "################",
      "################",
      "################",
      "################",
      "################",
      "################",
      "################",
      "################",
      "################",
      "################"
    ]
  ]
}